[2021-05-21 15:32:56,845] INFO: App startup in /home/anton/PycharmProjects/epam_project/src/__init__.py:27
[2021-05-21 15:32:56,849] INFO: App startup in /home/anton/PycharmProjects/epam_project/src/__init__.py:27
[2021-05-24 13:13:13,881] INFO: App startup in /home/anton/PycharmProjects/epam_project/src/__init__.py:27
[2021-05-24 13:13:36,142] ERROR: Exception on / [GET] in /home/anton/PycharmProjects/epam_project/venv/lib/python3.8/site-packages/flask/app.py:1891
Traceback (most recent call last):
  File "/home/anton/PycharmProjects/epam_project/venv/lib/python3.8/site-packages/pymysql/connections.py", line 613, in connect
    sock = socket.create_connection(
  File "/usr/lib/python3.8/socket.py", line 787, in create_connection
    for res in getaddrinfo(host, port, 0, SOCK_STREAM):
  File "/usr/lib/python3.8/socket.py", line 918, in getaddrinfo
    for res in _socket.getaddrinfo(host, port, family, type, proto, flags):
socket.gaierror: [Errno -3] Temporary failure in name resolution

During handling of the above exception, another exception occurred:

Traceback (most recent call last):
  File "/home/anton/PycharmProjects/epam_project/venv/lib/python3.8/site-packages/sqlalchemy/engine/base.py", line 3141, in _wrap_pool_connect
    return fn()
  File "/home/anton/PycharmProjects/epam_project/venv/lib/python3.8/site-packages/sqlalchemy/pool/base.py", line 301, in connect
    return _ConnectionFairy._checkout(self)
  File "/home/anton/PycharmProjects/epam_project/venv/lib/python3.8/site-packages/sqlalchemy/pool/base.py", line 755, in _checkout
    fairy = _ConnectionRecord.checkout(pool)
  File "/home/anton/PycharmProjects/epam_project/venv/lib/python3.8/site-packages/sqlalchemy/pool/base.py", line 419, in checkout
    rec = pool._do_get()
  File "/home/anton/PycharmProjects/epam_project/venv/lib/python3.8/site-packages/sqlalchemy/pool/impl.py", line 145, in _do_get
    self._dec_overflow()
  File "/home/anton/PycharmProjects/epam_project/venv/lib/python3.8/site-packages/sqlalchemy/util/langhelpers.py", line 70, in __exit__
    compat.raise_(
  File "/home/anton/PycharmProjects/epam_project/venv/lib/python3.8/site-packages/sqlalchemy/util/compat.py", line 211, in raise_
    raise exception
  File "/home/anton/PycharmProjects/epam_project/venv/lib/python3.8/site-packages/sqlalchemy/pool/impl.py", line 142, in _do_get
    return self._create_connection()
  File "/home/anton/PycharmProjects/epam_project/venv/lib/python3.8/site-packages/sqlalchemy/pool/base.py", line 247, in _create_connection
    return _ConnectionRecord(self)
  File "/home/anton/PycharmProjects/epam_project/venv/lib/python3.8/site-packages/sqlalchemy/pool/base.py", line 362, in __init__
    self.__connect(first_connect_check=True)
  File "/home/anton/PycharmProjects/epam_project/venv/lib/python3.8/site-packages/sqlalchemy/pool/base.py", line 605, in __connect
    pool.logger.debug("Error on connect(): %s", e)
  File "/home/anton/PycharmProjects/epam_project/venv/lib/python3.8/site-packages/sqlalchemy/util/langhelpers.py", line 70, in __exit__
    compat.raise_(
  File "/home/anton/PycharmProjects/epam_project/venv/lib/python3.8/site-packages/sqlalchemy/util/compat.py", line 211, in raise_
    raise exception
  File "/home/anton/PycharmProjects/epam_project/venv/lib/python3.8/site-packages/sqlalchemy/pool/base.py", line 599, in __connect
    connection = pool._invoke_creator(self)
  File "/home/anton/PycharmProjects/epam_project/venv/lib/python3.8/site-packages/sqlalchemy/engine/create.py", line 578, in connect
    return dialect.connect(*cargs, **cparams)
  File "/home/anton/PycharmProjects/epam_project/venv/lib/python3.8/site-packages/sqlalchemy/engine/default.py", line 583, in connect
    return self.dbapi.connect(*cargs, **cparams)
  File "/home/anton/PycharmProjects/epam_project/venv/lib/python3.8/site-packages/pymysql/connections.py", line 353, in __init__
    self.connect()
  File "/home/anton/PycharmProjects/epam_project/venv/lib/python3.8/site-packages/pymysql/connections.py", line 664, in connect
    raise exc
pymysql.err.OperationalError: (2003, "Can't connect to MySQL server on 'd3y0lbg7abxmbuoi.chr7pe7iynqr.eu-west-1.rds.amazonaws.com' ([Errno -3] Temporary failure in name resolution)")

The above exception was the direct cause of the following exception:

Traceback (most recent call last):
  File "/home/anton/PycharmProjects/epam_project/venv/lib/python3.8/site-packages/flask/app.py", line 2447, in wsgi_app
    response = self.full_dispatch_request()
  File "/home/anton/PycharmProjects/epam_project/venv/lib/python3.8/site-packages/flask/app.py", line 1945, in full_dispatch_request
    self.try_trigger_before_first_request_functions()
  File "/home/anton/PycharmProjects/epam_project/venv/lib/python3.8/site-packages/flask/app.py", line 1993, in try_trigger_before_first_request_functions
    func()
  File "/home/anton/PycharmProjects/epam_project/src/__init__.py", line 45, in setup
    db.create_all()
  File "/home/anton/PycharmProjects/epam_project/venv/lib/python3.8/site-packages/flask_sqlalchemy/__init__.py", line 1094, in create_all
    self._execute_for_all_tables(app, bind, 'create_all')
  File "/home/anton/PycharmProjects/epam_project/venv/lib/python3.8/site-packages/flask_sqlalchemy/__init__.py", line 1086, in _execute_for_all_tables
    op(bind=self.get_engine(app, bind), **extra)
  File "/home/anton/PycharmProjects/epam_project/venv/lib/python3.8/site-packages/sqlalchemy/sql/schema.py", line 4744, in create_all
    bind._run_ddl_visitor(
  File "/home/anton/PycharmProjects/epam_project/venv/lib/python3.8/site-packages/sqlalchemy/engine/base.py", line 3007, in _run_ddl_visitor
    with self.begin() as conn:
  File "/home/anton/PycharmProjects/epam_project/venv/lib/python3.8/site-packages/sqlalchemy/engine/base.py", line 2923, in begin
    conn = self.connect(close_with_result=close_with_result)
  File "/home/anton/PycharmProjects/epam_project/venv/lib/python3.8/site-packages/sqlalchemy/engine/base.py", line 3095, in connect
    return self._connection_cls(self, close_with_result=close_with_result)
  File "/home/anton/PycharmProjects/epam_project/venv/lib/python3.8/site-packages/sqlalchemy/engine/base.py", line 91, in __init__
    else engine.raw_connection()
  File "/home/anton/PycharmProjects/epam_project/venv/lib/python3.8/site-packages/sqlalchemy/engine/base.py", line 3174, in raw_connection
    return self._wrap_pool_connect(self.pool.connect, _connection)
  File "/home/anton/PycharmProjects/epam_project/venv/lib/python3.8/site-packages/sqlalchemy/engine/base.py", line 3144, in _wrap_pool_connect
    Connection._handle_dbapi_exception_noconnection(
  File "/home/anton/PycharmProjects/epam_project/venv/lib/python3.8/site-packages/sqlalchemy/engine/base.py", line 2003, in _handle_dbapi_exception_noconnection
    util.raise_(
  File "/home/anton/PycharmProjects/epam_project/venv/lib/python3.8/site-packages/sqlalchemy/util/compat.py", line 211, in raise_
    raise exception
  File "/home/anton/PycharmProjects/epam_project/venv/lib/python3.8/site-packages/sqlalchemy/engine/base.py", line 3141, in _wrap_pool_connect
    return fn()
  File "/home/anton/PycharmProjects/epam_project/venv/lib/python3.8/site-packages/sqlalchemy/pool/base.py", line 301, in connect
    return _ConnectionFairy._checkout(self)
  File "/home/anton/PycharmProjects/epam_project/venv/lib/python3.8/site-packages/sqlalchemy/pool/base.py", line 755, in _checkout
    fairy = _ConnectionRecord.checkout(pool)
  File "/home/anton/PycharmProjects/epam_project/venv/lib/python3.8/site-packages/sqlalchemy/pool/base.py", line 419, in checkout
    rec = pool._do_get()
  File "/home/anton/PycharmProjects/epam_project/venv/lib/python3.8/site-packages/sqlalchemy/pool/impl.py", line 145, in _do_get
    self._dec_overflow()
  File "/home/anton/PycharmProjects/epam_project/venv/lib/python3.8/site-packages/sqlalchemy/util/langhelpers.py", line 70, in __exit__
    compat.raise_(
  File "/home/anton/PycharmProjects/epam_project/venv/lib/python3.8/site-packages/sqlalchemy/util/compat.py", line 211, in raise_
    raise exception
  File "/home/anton/PycharmProjects/epam_project/venv/lib/python3.8/site-packages/sqlalchemy/pool/impl.py", line 142, in _do_get
    return self._create_connection()
  File "/home/anton/PycharmProjects/epam_project/venv/lib/python3.8/site-packages/sqlalchemy/pool/base.py", line 247, in _create_connection
    return _ConnectionRecord(self)
  File "/home/anton/PycharmProjects/epam_project/venv/lib/python3.8/site-packages/sqlalchemy/pool/base.py", line 362, in __init__
    self.__connect(first_connect_check=True)
  File "/home/anton/PycharmProjects/epam_project/venv/lib/python3.8/site-packages/sqlalchemy/pool/base.py", line 605, in __connect
    pool.logger.debug("Error on connect(): %s", e)
  File "/home/anton/PycharmProjects/epam_project/venv/lib/python3.8/site-packages/sqlalchemy/util/langhelpers.py", line 70, in __exit__
    compat.raise_(
  File "/home/anton/PycharmProjects/epam_project/venv/lib/python3.8/site-packages/sqlalchemy/util/compat.py", line 211, in raise_
    raise exception
  File "/home/anton/PycharmProjects/epam_project/venv/lib/python3.8/site-packages/sqlalchemy/pool/base.py", line 599, in __connect
    connection = pool._invoke_creator(self)
  File "/home/anton/PycharmProjects/epam_project/venv/lib/python3.8/site-packages/sqlalchemy/engine/create.py", line 578, in connect
    return dialect.connect(*cargs, **cparams)
  File "/home/anton/PycharmProjects/epam_project/venv/lib/python3.8/site-packages/sqlalchemy/engine/default.py", line 583, in connect
    return self.dbapi.connect(*cargs, **cparams)
  File "/home/anton/PycharmProjects/epam_project/venv/lib/python3.8/site-packages/pymysql/connections.py", line 353, in __init__
    self.connect()
  File "/home/anton/PycharmProjects/epam_project/venv/lib/python3.8/site-packages/pymysql/connections.py", line 664, in connect
    raise exc
sqlalchemy.exc.OperationalError: (pymysql.err.OperationalError) (2003, "Can't connect to MySQL server on 'd3y0lbg7abxmbuoi.chr7pe7iynqr.eu-west-1.rds.amazonaws.com' ([Errno -3] Temporary failure in name resolution)")
(Background on this error at: http://sqlalche.me/e/14/e3q8)
